<?xml version="1.0"?>

<robot name="bebop">

  <xacro:property name="pi" value="3.1415926535897931" />
  <!-- +- 35 degrees -->
  <!-- Main quadrotor link -->
    <link name="base_link">
        <inertial>
        <mass value="0.399" />
        <origin xyz="0 0 0" />
        <inertia ixx="0.01152" ixy="0.0" ixz="0.0" iyy="0.01152" iyz="0.0" izz="0.0218" />
        <!-- Inertia from hector quadrotor, sorry! -->
        </inertial>

        <visual>
        <origin xyz="0 0 0" rpy="0 0 0" />
        <geometry>
            <mesh filename="/home/shaswatgarg/ros_ws/src/rl_path_planning/rl_path_planning/environment/PyBulletEnv/Quadrotor/Assets/meshes/bebop_model.stl"/>
        </geometry>
        <material name="blue">
            <color rgba="0 0.4 0.6 1"/>
        </material>
        </visual>

        <collision>
        <origin xyz="0 0 0" rpy="0 0 0" />
        <geometry>
            <mesh filename="/home/shaswatgarg/ros_ws/src/rl_path_planning/rl_path_planning/environment/PyBulletEnv/Quadrotor/Assets/meshes/bebop_model.stl"/>
        </geometry>
        </collision>
    </link>

    <link name="camera_base_link"></link>
    <link name="camera_pan_link"></link>
    <link name="camera_tilt_link"></link>
    <link name="camera_optical"></link>

    <joint name="base_link_joint" type="fixed">
        <origin xyz="0.1 0 0.0" rpy="0 0 0" />
        <parent link="base_link"/>
        <child link="camera_base_link" />
    </joint>

    <joint name="camera_pan_joint" type="revolute">
        <origin xyz="0 0 0" rpy="0 0 0" />
        <parent link="camera_base_link" />
        <child link="camera_pan_link" />
        <axis xyz="0 0 1" />
        <limit lower="-0.6108652381980153" upper="0.6108652381980153"
        effort="50" velocity="2.0" />
    </joint>

    <joint name="camera_tilt_joint" type="revolute">
        <origin xyz="0 0 0" rpy="0 0 0" />
        <parent link="camera_pan_link" />
        <child link="camera_tilt_link" />
        <axis xyz="0 1 0" />
        <limit lower="-0.6108652381980153" upper="0.6108652381980153"
        effort="50" velocity="2.0" />
    </joint>

    <joint name="camera_optical_joint" type="fixed">
        <origin xyz="0 0 0" rpy="-3.1415926535897931/2 0 -3.1415926535897931/2" />
        <parent link="camera_tilt_link" />
        <child link="camera_optical" />
    </joint>
</robot>